Workbook

Sheet Read Me
A1: Southern Water Corp. Financial Analysis
N4: Juti
A11: In this unit, you've learned about the fundamentals of financial analysis spanning revenues, expenses and profitability.
A12: In this case study, we'll seek to unpack these concepts, combining the financial analysis skills you've learned and have you apply this through your budding Excel capabilities!
A13: This case study will emphasise both your use of the SUMIFS Formula as well as your charting capabilities, where you'll use these charts for a PowerPoint presentation you'll create at the end of this analysis!
A14: Good luck and let's get started!
A16: What do the tab colours in this workbook mean?
A17: Throughout the Case Study, we've split this into three sections. As you cover the relevant financial concepts, you'll apply what you've learned in the exercise tabs. The order of completion is below: 1) Revenue Sub Unit - Revenue Analysis 2) Expense Sub Unit - Expense Analysis 3) Profitability Sub Unit - Profitability (EBIT) Analysis
A18: Unpacking the Data Repository Table
A19: The data repository table might look scary at first, but all the data is logically grouped in a manner where the table can be read left-to-right.
A20: We've included an example below to break down how you can interpret this information.
A32: Definitions
A33: We've included a high-level breakdown that explains the different columns you will deal with in the data repository table. Please read through this and familiarise yourself with what these columns mean.
A35: Account Type | B35: This column provides information on whether the dataset is referencing Financial Actuals (Money Spent) or Water Actuals (Volume of Water Produced).
A36: Value Drivers | B36: This is a pre-filled column mapping each Accounting Centre Code and Accounting Centre Code Element to either a Revenue Generating Activity (Revenues) or Cost Generating Activity (Expenses).
A37: Unit | B37: There are three desalination units or plants (facilities) owned by Southern Water Corp. These are the Kootha, Surjek and Jutik desalination units. The Unit column indicates, for that row of data, which Unit it applies towards.
A38: Month | B38: This represents the month that data was calculated for.
A39: Month (Number) | B39: This represents the month in numerical form.
A40: Accounting Code Centre | B40: Every row is mapped to an Accounting Code Centre. Based off the Accounting Code Centre (ACC) and the textual description, we know that all ACC's that mention Sales, are Profit Centres, and all ACC's that mention Costs, are Cost Centres. In Financial Accounting, Revenue Generating Activities are mapped to Profit Centres (i.e. They generate profit), whilst Cost Generating Activities are mapped to Cost Centres (i.e. They generate costs).
A41: Accounting Code Centre Element | B41: An Accounting Code Centre Element (ACCE) is made up of 'elements' which tie into the Accounting Code Centre.
A42: Unit of Measure | B42: Every Row of Data has a Unit of Measure (UoM) associated with this. E.g. Financial data is measured in dollars, whilst Water Production data is measure in Giga-Litres.
A43: Row Data | B43: This is the unique value that is stored for every row entry.
A46: Value Driver Trees
A47: Below we've included the Value Driver Trees for Revenues, Expenses and Profitability Analysis, to better help you understand how the dataset is all connected. Use this if you're feeling unsure of how to calculate Revenues, Expenses or Profitability.

Sheet Data Repository Table
A1: Account Type | B1: Value Drivers | C1: Unit | D1: Month | E1: Month (Number) | F1: Accounting Code Centre | G1: Accounting Code Centre Element | H1: Unit of Measure | I1: Row Data
A2: Financial Actual | B2: Revenue | C2: Kootha | D2: 41456 | E2: =MONTH(D2) -> 7 | F2: 001 Private Water Hedge Sales | G2: W-Transact (0211) - Soft | H2: $ | I2: 1473589
A3: Financial Actual | B3: Revenue | C3: Kootha | D3: 41487 | E3: =MONTH(D3) -> 8 | F3: 001 Private Water Hedge Sales | G3: W-Transact (0211) - Soft | H3: $ | I3: 1419296.1
A4: Financial Actual | B4: Revenue | C4: Kootha | D4: 41518 | E4: =MONTH(D4) -> 9 | F4: 001 Private Water Hedge Sales | G4: W-Transact (0211) - Soft | H4: $ | I4: 1310673.2
A5: Financial Actual | B5: Revenue | C5: Kootha | D5: 41548 | E5: =MONTH(D5) -> 10 | F5: 001 Private Water Hedge Sales | G5: W-Transact (0211) - Soft | H5: $ | I5: 1301024.7
A6: Financial Actual | B6: Revenue | C6: Kootha | D6: 41579 | E6: =MONTH(D6) -> 11 | F6: 001 Private Water Hedge Sales | G6: W-Transact (0211) - Soft | H6: $ | I6: 1373822.9
A7: Financial Actual | B7: Revenue | C7: Kootha | D7: 41609 | E7: =MONTH(D7) -> 12 | F7: 001 Private Water Hedge Sales | G7: W-Transact (0211) - Soft | H7: $ | I7: 1340623
A8: Financial Actual | B8: Revenue | C8: Kootha | D8: 41640 | E8: =MONTH(D8) -> 1 | F8: 001 Private Water Hedge Sales | G8: W-Transact (0211) - Soft | H8: $ | I8: 1948962.6
A9: Financial Actual | B9: Revenue | C9: Kootha | D9: 41671 | E9: =MONTH(D9) -> 2 | F9: 001 Private Water Hedge Sales | G9: W-Transact (0211) - Soft | H9: $ | I9: 1725161.7
A10: Financial Actual | B10: Revenue | C10: Kootha | D10: 41699 | E10: =MONTH(D10) -> 3 | F10: 001 Private Water Hedge Sales | G10: W-Transact (0211) - Soft | H10: $ | I10: 1818208.6
A11: Financial Actual | B11: Revenue | C11: Kootha | D11: 41730 | E11: =MONTH(D11) -> 4 | F11: 001 Private Water Hedge Sales | G11: W-Transact (0211) - Soft | H11: $ | I11: 1328501.7
A12: Financial Actual | B12: Revenue | C12: Kootha | D12: 41760 | E12: =MONTH(D12) -> 5 | F12: 001 Private Water Hedge Sales | G12: W-Transact (0211) - Soft | H12: $ | I12: 1344117.3
A13: Financial Actual | B13: Revenue | C13: Kootha | D13: 41791 | E13: =MONTH(D13) -> 6 | F13: 001 Private Water Hedge Sales | G13: W-Transact (0211) - Soft | H13: $ | I13: 1291609.1
... A373: Financial Actual | B373: Expenses | C373: Surjek | D373: 41791 | E373: =MONTH(D373) -> 6 | F373: Labour Costs | G373: Labour-Costs (001) | H373: $ | I373: 1891504.3
A374: Financial Actual | B374: Expenses | C374: Jutik | D374: 41456 | E374: 7 | F374: Chemical Costs | G374: Chem-Exp (001) | H374: $ | I374: 1625596.3
A375: Financial Actual | B375: Expenses | C375: Jutik | D375: 41487 | E375: 8 | F375: Chemical Costs | G375: Chem-Exp (001) | H375: $ | I375: 1295067.8
A376: Financial Actual | B376: Expenses | C376: Jutik | D376: 41518 | E376: 9 | F376: Chemical Costs | G376: Chem-Exp (001) | H376: $ | I376: 1750624.9
A377: Financial Actual | B377: Expenses | C377: Jutik | D377: 41548 | E377: 10 | F377: Chemical Costs | G377: Chem-Exp (001) | H377: $ | I377: 1472529.4
A378: Financial Actual | B378: Expenses | C378: Jutik | D378: 41579 | E378: 11 | F378: Chemical Costs | G378: Chem-Exp (001) | H378: $ | I378: 1252200.5
A379: Financial Actual | B379: Expenses | C379: Jutik | D379: 41609 | E379: 12 | F379: Chemical Costs | G379: Chem-Exp (001) | H379: $ | I379: 1406782.7
A380: Financial Actual | B380: Expenses | C380: Jutik | D380: 41640 | E380: 1 | F380: Chemical Costs | G380: Chem-Exp (001) | H380: $ | I380: 1877449.5
A381: Financial Actual | B381: Expenses | C381: Jutik | D381: 41671 | E381: 2 | F381: Chemical Costs | G381: Chem-Exp (001) | H381: $ | I381: 1912219.2
A382: Financial Actual | B382: Expenses | C382: Jutik | D382: 41699 | E382: 3 | F382: Chemical Costs | G382: Chem-Exp (001) | H382: $ | I382: 2266625.2
A383: Financial Actual | B383: Expenses | C383: Jutik | D383: 41730 | E383: 4 | F383: Chemical Costs | G383: Chem-Exp (001) | H383: $ | I383: 2234200.6
A384: Financial Actual | B384: Expenses | C384: Jutik | D384: 41760 | E384: 5 | F384: Chemical Costs | G384: Chem-Exp (001) | H384: $ | I384: 2593715.6
A385: Financial Actual | B385: Expenses | C385: Jutik | D385: 41791 | E385: 6 | F385: Chemical Costs | G385: Chem-Exp (001) | H385: $ | I385: 2274807.8
... A505: Water Production Actuals | B505: None | C505: Jutik | D505: 41791 | E505: 6 | F505: None | G505: None | H505: Giga-Litre | I505: 220.38033

Sheet Revenue Analysis
A1: Revenue Analysis - Part I
A2: In Financial Data Analysis, Revenue Analysis speaks primarily to understanding which product(s) generate the most revenues and whether we can identify any aspect of seasonality towards these trends or not.
A3: The importance of this is that we are able to clearly understand which product(s) generate the most revenues and least revenues and this forms the first part of our puzzle.
A4: If a product generates a lot of revenues, but the expenses are greater than the revenues - this isn't a good news story.
A5: However, if the product generates a lot of revenues, and the expenses are well below the revenues - we may have a product which is performing well.
A6: Let's take a look at how Southern Water Corps Revenue Analysis looks like by calculating the Revenues for each of the products and asking ourselves - what does the data tell us?
A7: Let's get started!
A8: Q1. For each of the three Southern Water Corp. Desalination Plants, they produce desalinated water which is then consumed via private, public or residential usage. Please calculate the monthly revenues for Kootha, Surjek and Jutik and put this in the table below.
A9: Hint: You'll be utilizing the SUMIFS function here to assist you with the exercise. Remember the Syntax follows: =SUMIFS(Sum_Range, Criteria_Range_1, Criteria…)
A10: Unit | B10: Value Driver | C10: Accounting Code Centre | D10: Accounting Code Centre Element | E10: 41456 | F10: 41487 | G10: 41518 | H10: 41548 | I10: 41579 | J10: 41609 | K10: 41640 | L10: 41671 | M10: 41699 | N10: 41730 | O10: 41760 | P10: 41791
Q11: Total
A12: Kootha | B12: Revenue | C12: 001 Private Water Hedge Sales | D12: W-Transact (0211) - Soft | E12: =SUMIFS('Data Repository Table'!$I:$I,'Data Repository Table'!$C:$C,'Revenue Analysis'!$A12,'Data Repository Table'!$B:$B,'Revenue Analysis'!$B12,'Data Repository Table'!$F:$F,'Revenue Analysis'!$C12,'Data Repository Table'!$G:$G,'Revenue Analysis'!$D12,'Data Repository Table'!$D:$D,'Revenue Analysis'!E$10) -> 1473589 | F12: =SUMIFS('Data Repository Table'!$I:$I,'Data Repository Table'!$C:$C,'Revenue Analysis'!$A12,'Data Repository Table'!$B:$B,'Revenue Analysis'!$B12,'Data Repository Table'!$F:$F,'Revenue Analysis'!$C12,'Data Repository Table'!$G:$G,'Revenue Analysis'!$D12,'Data Repository Table'!$D:$D,'Revenue Analysis'!F$10) -> 1419296.1 | G12: =SUMIFS('Data Repository Table'!$I:$I,'Data Repository Table'!$C:$C,'Revenue Analysis'!$A12,'Data Repository Table'!$B:$B,'Revenue Analysis'!$B12,'Data Repository Table'!$F:$F,'Revenue Analysis'!$C12,'Data Repository Table'!$G:$G,'Revenue Analysis'!$D12,'Data Repository Table'!$D:$D,'Revenue Analysis'!G$10) -> 1310673.2 | H12: =SUMIFS('Data Repository Table'!$I:$I,'Data Repository Table'!$C:$C,'Revenue Analysis'!$A12,'Data Repository Table'!$B:$B,'Revenue Analysis'!$B12,'Data Repository Table'!$F:$F,'Revenue Analysis'!$C12,'Data Repository Table'!$G:$G,'Revenue Analysis'!$D12,'Data Repository Table'!$D:$D,'Revenue Analysis'!H$10) -> 1301024.7 | I12: =SUMIFS('Data Repository Table'!$I:$I,'Data Repository Table'!$C:$C,'Revenue Analysis'!$A12,'Data Repository Table'!$B:$B,'Revenue Analysis'!$B12,'Data Repository Table'!$F:$F,'Revenue Analysis'!$C12,'Data Repository Table'!$G:$G,'Revenue Analysis'!$D12,'Data Repository Table'!$D:$D,'Revenue Analysis'!I$10) -> 1373822.9 | J12: =SUMIFS('Data Repository Table'!$I:$I,'Data Repository Table'!$C:$C,'Revenue Analysis'!$A12,'Data Repository Table'!$B:$B,'Revenue Analysis'!$B12,'Data Repository Table'!$F:$F,'Revenue Analysis'!$C12,'Data Repository Table'!$G:$G,'Revenue Analysis'!$D12,'Data Repository Table'!$D:$D,'Revenue Analysis'!J$10) -> 1340623 | K12: =SUMIFS('Data Repository Table'!$I:$I,'Data Repository Table'!$C:$C,'Revenue Analysis'!$A12,'Data Repository Table'!$B:$B,'Revenue Analysis'!$B12,'Data Repository Table'!$F:$F,'Revenue Analysis'!$C12,'Data Repository Table'!$G:$G,'Revenue Analysis'!$D12,'Data Repository Table'!$D:$D,'Revenue Analysis'!K$10) -> 1948962.6 | L12: =SUMIFS('Data Repository Table'!$I:$I,'Data Repository Table'!$C:$C,'Revenue Analysis'!$A12,'Data Repository Table'!$B:$B,'Revenue Analysis'!$B12,'Data Repository Table'!$F:$F,'Revenue Analysis'!$C12,'Data Repository Table'!$G:$G,'Revenue Analysis'!$D12,'Data Repository Table'!$D:$D,'Revenue Analysis'!L$10) -> 1725161.7 | ... P12: =SUMIFS('Data Repository Table'!$I:$I,'Data Repository Table'!$C:$C,'Revenue Analysis'!$A12,'Data Repository Table'!$B:$B,'Revenue Analysis'!$B12,'Data Repository Table'!$F:$F,'Revenue Analysis'!$C12,'Data Repository Table'!$G:$G,'Revenue Analysis'!$D12,'Data Repository Table'!$D:$D,'Revenue Analysis'!P$10) -> 1291609.1 | Q12: =SUM(E12:P12) -> 17675590
A13: Kootha | B13: Revenue | C13: 001 Private Water Hedge Sales | D13: W-Transact (0212) - Hard | E13: =SUMIFS('Data Repository Table'!$I:$I,'Data Repository Table'!$C:$C,'Revenue Analysis'!$A13,'Data Repository Table'!$B:$B,'Revenue Analysis'!$B13,'Data Repository Table'!$F:$F,'Revenue Analysis'!$C13,'Data Repository Table'!$G:$G,'Revenue Analysis'!$D13,'Data Repository Table'!$D:$D,'Revenue Analysis'!E$10) -> 1620948 | F13: =SUMIFS('Data Repository Table'!$I:$I,'Data Repository Table'!$C:$C,'Revenue Analysis'!$A13,'Data Repository Table'!$B:$B,'Revenue Analysis'!$B13,'Data Repository Table'!$F:$F,'Revenue Analysis'!$C13,'Data Repository Table'!$G:$G,'Revenue Analysis'!$D13,'Data Repository Table'!$D:$D,'Revenue Analysis'!F$10) -> 1561225.7 | G13: =SUMIFS('Data Repository Table'!$I:$I,'Data Repository Table'!$C:$C,'Revenue Analysis'!$A13,'Data Repository Table'!$B:$B,'Revenue Analysis'!$B13,'Data Repository Table'!$F:$F,'Revenue Analysis'!$C13,'Data Repository Table'!$G:$G,'Revenue Analysis'!$D13,'Data Repository Table'!$D:$D,'Revenue Analysis'!G$10) -> 1441740.5 | H13: =SUMIFS('Data Repository Table'!$I:$I,'Data Repository Table'!$C:$C,'Revenue Analysis'!$A13,'Data Repository Table'!$B:$B,'Revenue Analysis'!$B13,'Data Repository Table'!$F:$F,'Revenue Analysis'!$C13,'Data Repository Table'!$G:$G,'Revenue Analysis'!$D13,'Data Repository Table'!$D:$D,'Revenue Analysis'!H$10) -> 1431127.2 | I13: =SUMIFS('Data Repository Table'!$I:$I,'Data Repository Table'!$C:$C,'Revenue Analysis'!$A13,'Data Repository Table'!$B:$B,'Revenue Analysis'!$B13,'Data Repository Table'!$F:$F,'Revenue Analysis'!$C13,'Data Repository Table'!$G:$G,'Revenue Analysis'!$D13,'Data Repository Table'!$D:$D,'Revenue Analysis'!I$10) -> 1511205.1 | J13: =SUMIFS('Data Repository Table'!$I:$I,'Data Repository Table'!$C:$C,'Revenue Analysis'!$A13,'Data Repository Table'!$B:$B,'Revenue Analysis'!$B13,'Data Repository Table'!$F:$F,'Revenue Analysis'!$C13,'Data Repository Table'!$G:$G,'Revenue Analysis'!$D13,'Data Repository Table'!$D:$D,'Revenue Analysis'!J$10) -> 1474685.3 | K13: =SUMIFS('Data Repository Table'!$I:$I,'Data Repository Table'!$C:$C,'Revenue Analysis'!$A13,'Data Repository Table'!$B:$B,'Revenue Analysis'!$B13,'Data Repository Table'!$F:$F,'Revenue Analysis'!$C13,'Data Repository Table'!$G:$G,'Revenue Analysis'!$D13,'Data Repository Table'!$D:$D,'Revenue Analysis'!K$10) -> 2143858.8 | L13: =SUMIFS('Data Repository Table'!$I:$I,'Data Repository Table'!$C:$C,'Revenue Analysis'!$A13,'Data Repository Table'!$B:$B,'Revenue Analysis'!$B13,'Data Repository Table'!$F:$F,'Revenue Analysis'!$C13,'Data Repository Table'!$G:$G,'Revenue Analysis'!$D13,'Data Repository Table'!$D:$D,'Revenue Analysis'!L$10) -> 1897677.9 | ... P13: =SUMIFS('Data Repository Table'!$I:$I,'Data Repository Table'!$C:$C,'Revenue Analysis'!$A13,'Data Repository Table'!$B:$B,'Revenue Analysis'!$B13,'Data Repository Table'!$F:$F,'Revenue Analysis'!$C13,'Data Repository Table'!$G:$G,'Revenue Analysis'!$D13,'Data Repository Table'!$D:$D,'Revenue Analysis'!P$10) -> 1420770 | Q13: =SUM(E13:P13) -> 19443149
A14: Kootha | B14: Revenue | C14: 002 Public Sales | D14: W-Transact (0211) - Soft | E14: =SUMIFS('Data Repository Table'!$I:$I,'Data Repository Table'!$C:$C,'Revenue Analysis'!$A14,'Data Repository Table'!$B:$B,'Revenue Analysis'!$B14,'Data Repository Table'!$F:$F,'Revenue Analysis'!$C14,'Data Repository Table'!$G:$G,'Revenue Analysis'!$D14,'Data Repository Table'!$D:$D,'Revenue Analysis'!E$10) -> 567331.78 | F14: =SUMIFS('Data Repository Table'!$I:$I,'Data Repository Table'!$C:$C,'Revenue Analysis'!$A14,'Data Repository Table'!$B:$B,'Revenue Analysis'!$B14,'Data Repository Table'!$F:$F,'Revenue Analysis'!$C14,'Data Repository Table'!$G:$G,'Revenue Analysis'!$D14,'Data Repository Table'!$D:$D,'Revenue Analysis'!F$10) -> 546429 | G14: =SUMIFS('Data Repository Table'!$I:$I,'Data Repository Table'!$C:$C,'Revenue Analysis'!$A14,'Data Repository Table'!$B:$B,'Revenue Analysis'!$B14,'Data Repository Table'!$F:$F,'Revenue Analysis'!$C14,'Data Repository Table'!$G:$G,'Revenue Analysis'!$D14,'Data Repository Table'!$D:$D,'Revenue Analysis'!G$10) -> 504609.19 | H14: =SUMIFS('Data Repository Table'!$I:$I,'Data Repository Table'!$C:$C,'Revenue Analysis'!$A14,'Data Repository Table'!$B:$B,'Revenue Analysis'!$B14,'Data Repository Table'!$F:$F,'Revenue Analysis'!$C14,'Data Repository Table'!$G:$G,'Revenue Analysis'!$D14,'Data Repository Table'!$D:$D,'Revenue Analysis'!H$10) -> 500894.52 | I14: =SUMIFS('Data Repository Table'!$I:$I,'Data Repository Table'!$C:$C,'Revenue Analysis'!$A14,'Data Repository Table'!$B:$B,'Revenue Analysis'!$B14,'Data Repository Table'!$F:$F,'Revenue Analysis'!$C14,'Data Repository Table'!$G:$G,'Revenue Analysis'!$D14,'Data Repository Table'!$D:$D,'Revenue Analysis'!I$10) -> 528921.8 | J14: =SUMIFS('Data Repository Table'!$I:$I,'Data Repository Table'!$C:$C,'Revenue Analysis'!$A14,'Data Repository Table'!$B:$B,'Revenue Analysis'!$B14,'Data Repository Table'!$F:$F,'Revenue Analysis'!$C14,'Data Repository Table'!$G:$G,'Revenue Analysis'!$D14,'Data Repository Table'!$D:$D,'Revenue Analysis'!J$10) -> 516139.87 | K14: =SUMIFS('Data Repository Table'!$I:$I,'Data Repository Table'!$C:$C,'Revenue Analysis'!$A14,'Data Repository Table'!$B:$B,'Revenue Analysis'!$B14,'Data Repository Table'!$F:$F,'Revenue Analysis'!$C14,'Data Repository Table'!$G:$G,'Revenue Analysis'!$D14,'Data Repository Table'!$D:$D,'Revenue Analysis'!K$10) -> 750350.58 | L14: =SUMIFS('Data Repository Table'!$I:$I,'Data Repository Table'!$C:$C,'Revenue Analysis'!$A14,'Data Repository Table'!$B:$B,'Revenue Analysis'!$B14,'Data Repository Table'!$F:$F,'Revenue Analysis'!$C14,'Data Repository Table'!$G:$G,'Revenue Analysis'!$D14,'Data Repository Table'!$D:$D,'Revenue Analysis'!L$10) -> 664187.25 | ... P14: =SUMIFS('Data Repository Table'!$I:$I,'Data Repository Table'!$C:$C,'Revenue Analysis'!$A14,'Data Repository Table'!$B:$B,'Revenue Analysis'!$B14,'Data Repository Table'!$F:$F,'Revenue Analysis'!$C14,'Data Repository Table'!$G:$G,'Revenue Analysis'!$D14,'Data Repository Table'!$D:$D,'Revenue Analysis'!P$10) -> 497269.52 | Q14: =SUM(E14:P14) -> 6805102.1
A15: Kootha | B15: Revenue | C15: 002 Public Sales | D15: W-Transact (0212) - Hard | E15: =SUMIFS('Data Repository Table'!$I:$I,'Data Repository Table'!$C:$C,'Revenue Analysis'!$A15,'Data Repository Table'!$B:$B,'Revenue Analysis'!$B15,'Data Repository Table'!$F:$F,'Revenue Analysis'!$C15,'Data Repository Table'!$G:$G,'Revenue Analysis'!$D15,'Data Repository Table'!$D:$D,'Revenue Analysis'!E$10) -> 955954.05 | F15: =SUMIFS('Data Repository Table'!$I:$I,'Data Repository Table'!$C:$C,'Revenue Analysis'!$A15,'Data Repository Table'!$B:$B,'Revenue Analysis'!$B15,'Data Repository Table'!$F:$F,'Revenue Analysis'!$C15,'Data Repository Table'!$G:$G,'Revenue Analysis'!$D15,'Data Repository Table'!$D:$D,'Revenue Analysis'!F$10) -> 920732.86 | G15: =SUMIFS('Data Repository Table'!$I:$I,'Data Repository Table'!$C:$C,'Revenue Analysis'!$A15,'Data Repository Table'!$B:$B,'Revenue Analysis'!$B15,'Data Repository Table'!$F:$F,'Revenue Analysis'!$C15,'Data Repository Table'!$G:$G,'Revenue Analysis'!$D15,'Data Repository Table'!$D:$D,'Revenue Analysis'!G$10) -> 850266.48 | H15: =SUMIFS('Data Repository Table'!$I:$I,'Data Repository Table'!$C:$C,'Revenue Analysis'!$A15,'Data Repository Table'!$B:$B,'Revenue Analysis'!$B15,'Data Repository Table'!$F:$F,'Revenue Analysis'!$C15,'Data Repository Table'!$G:$G,'Revenue Analysis'!$D15,'Data Repository Table'!$D:$D,'Revenue Analysis'!H$10) -> 844007.27 | I15: =SUMIFS('Data Repository Table'!$I:$I,'Data Repository Table'!$C:$C,'Revenue Analysis'!$A15,'Data Repository Table'!$B:$B,'Revenue Analysis'!$B15,'Data Repository Table'!$F:$F,'Revenue Analysis'!$C15,'Data Repository Table'!$G:$G,'Revenue Analysis'!$D15,'Data Repository Table'!$D:$D,'Revenue Analysis'!I$10) -> 891233.24 | J15: =SUMIFS('Data Repository Table'!$I:$I,'Data Repository Table'!$C:$C,'Revenue Analysis'!$A15,'Data Repository Table'!$B:$B,'Revenue Analysis'!$B15,'Data Repository Table'!$F:$F,'Revenue Analysis'!$C15,'Data Repository Table'!$G:$G,'Revenue Analysis'!$D15,'Data Repository Table'!$D:$D,'Revenue Analysis'!J$10) -> 869695.68 | K15: =SUMIFS('Data Repository Table'!$I:$I,'Data Repository Table'!$C:$C,'Revenue Analysis'!$A15,'Data Repository Table'!$B:$B,'Revenue Analysis'!$B15,'Data Repository Table'!$F:$F,'Revenue Analysis'!$C15,'Data Repository Table'!$G:$G,'Revenue Analysis'!$D15,'Data Repository Table'!$D:$D,'Revenue Analysis'!K$10) -> 1264340.7 | L15: =SUMIFS('Data Repository Table'!$I:$I,'Data Repository Table'!$C:$C,'Revenue Analysis'!$A15,'Data Repository Table'!$B:$B,'Revenue Analysis'!$B15,'Data Repository Table'!$F:$F,'Revenue Analysis'!$C15,'Data Repository Table'!$G:$G,'Revenue Analysis'!$D15,'Data Repository Table'!$D:$D,'Revenue Analysis'!L$10) -> 1119155.5 | ... P15: =SUMIFS('Data Repository Table'!$I:$I,'Data Repository Table'!$C:$C,'Revenue Analysis'!$A15,'Data Repository Table'!$B:$B,'Revenue Analysis'!$B15,'Data Repository Table'!$F:$F,'Revenue Analysis'!$C15,'Data Repository Table'!$G:$G,'Revenue Analysis'!$D15,'Data Repository Table'!$D:$D,'Revenue Analysis'!P$10) -> 837899.14 | Q15: =SUM(E15:P15) -> 11466597
A16: Kootha | B16: Revenue | C16: 003 Residential Sales | D16: W-Transact (0211) - Soft | E16: =SUMIFS('Data Repository Table'!$I:$I,'Data Repository Table'!$C:$C,'Revenue Analysis'!$A16,'Data Repository Table'!$B:$B,'Revenue Analysis'!$B16,'Data Repository Table'!$F:$F,'Revenue Analysis'!$C16,'Data Repository Table'!$G:$G,'Revenue Analysis'!$D16,'Data Repository Table'!$D:$D,'Revenue Analysis'!E$10) -> 1296758.4 | F16: =SUMIFS('Data Repository Table'!$I:$I,'Data Repository Table'!$C:$C,'Revenue Analysis'!$A16,'Data Repository Table'!$B:$B,'Revenue Analysis'!$B16,'Data Repository Table'!$F:$F,'Revenue Analysis'!$C16,'Data Repository Table'!$G:$G,'Revenue Analysis'!$D16,'Data Repository Table'!$D:$D,'Revenue Analysis'!F$10) -> 1248980.6 | G16: =SUMIFS('Data Repository Table'!$I:$I,'Data Repository Table'!$C:$C,'Revenue Analysis'!$A16,'Data Repository Table'!$B:$B,'Revenue Analysis'!$B16,'Data Repository Table'!$F:$F,'Revenue Analysis'!$C16,'Data Repository Table'!$G:$G,'Revenue Analysis'!$D16,'Data Repository Table'!$D:$D,'Revenue Analysis'!G$10) -> 1153392.4 | H16: =SUMIFS('Data Repository Table'!$I:$I,'Data Repository Table'!$C:$C,'Revenue Analysis'!$A16,'Data Repository Table'!$B:$B,'Revenue Analysis'!$B16,'Data Repository Table'!$F:$F,'Revenue Analysis'!$C16,'Data Repository Table'!$G:$G,'Revenue Analysis'!$D16,'Data Repository Table'!$D:$D,'Revenue Analysis'!H$10) -> 1144901.8 | I16: =SUMIFS('Data Repository Table'!$I:$I,'Data Repository Table'!$C:$C,'Revenue Analysis'!$A16,'Data Repository Table'!$B:$B,'Revenue Analysis'!$B16,'Data Repository Table'!$F:$F,'Revenue Analysis'!$C16,'Data Repository Table'!$G:$G,'Revenue Analysis'!$D16,'Data Repository Table'!$D:$D,'Revenue Analysis'!I$10) -> 1208964.1 | J16: =SUMIFS('Data Repository Table'!$I:$I,'Data Repository Table'!$C:$C,'Revenue Analysis'!$A16,'Data Repository Table'!$B:$B,'Revenue Analysis'!$B16,'Data Repository Table'!$F:$F,'Revenue Analysis'!$C16,'Data Repository Table'!$G:$G,'Revenue Analysis'!$D16,'Data Repository Table'!$D:$D,'Revenue Analysis'!J$10) -> 1179748.3 | K16: =SUMIFS('Data Repository Table'!$I:$I,'Data Repository Table'!$C:$C,'Revenue Analysis'!$A16,'Data Repository Table'!$B:$B,'Revenue Analysis'!$B16,'Data Repository Table'!$F:$F,'Revenue Analysis'!$C16,'Data Repository Table'!$G:$G,'Revenue Analysis'!$D16,'Data Repository Table'!$D:$D,'Revenue Analysis'!K$10) -> 1715087 | L16: =SUMIFS('Data Repository Table'!$I:$I,'Data Repository Table'!$C:$C,'Revenue Analysis'!$A16,'Data Repository Table'!$B:$B,'Revenue Analysis'!$B16,'Data Repository Table'!$F:$F,'Revenue Analysis'!$C16,'Data Repository Table'!$G:$G,'Revenue Analysis'!$D16,'Data Repository Table'!$D:$D,'Revenue Analysis'!L$10) -> 1518142.3 | ... P16: =SUMIFS('Data Repository Table'!$I:$I,'Data Repository Table'!$C:$C,'Revenue Analysis'!$A16,'Data Repository Table'!$B:$B,'Revenue Analysis'!$B16,'Data Repository Table'!$F:$F,'Revenue Analysis'!$C16,'Data Repository Table'!$G:$G,'Revenue Analysis'!$D16,'Data Repository Table'!$D:$D,'Revenue Analysis'!P$10) -> 1136616 | Q16: =SUM(E16:P16) -> 15554519
A18: Surjek | B18: Revenue | C18: 001 Private Water Hedge Sales | D18: W-Transact (0211) - Soft | E18: =SUMIFS('Data Repository Table'!$I:$I,'Data Repository Table'!$C:$C,'Revenue Analysis'!$A18,'Data Repository Table'!$B:$B,'Revenue Analysis'!$B18,'Data Repository Table'!$F:$F,'Revenue Analysis'!$C18,'Data Repository Table'!$G:$G,'Revenue Analysis'!$D18,'Data Repository Table'!$D:$D,'Revenue Analysis'!E$10) -> 2406673.7 | F18: =SUMIFS('Data Repository Table'!$I:$I,'Data Repository Table'!$C:$C,'Revenue Analysis'!$A18,'Data Repository Table'!$B:$B,'Revenue Analysis'!$B18,'Data Repository Table'!$F:$F,'Revenue Analysis'!$C18,'Data Repository Table'!$G:$G,'Revenue Analysis'!$D18,'Data Repository Table'!$D:$D,'Revenue Analysis'!F$10) -> 2028377 | G18: =SUMIFS('Data Repository Table'!$I:$I,'Data Repository Table'!$C:$C,'Revenue Analysis'!$A18,'Data Repository Table'!$B:$B,'Revenue Analysis'!$B18,'Data Repository Table'!$F:$F,'Revenue Analysis'!$C18,'Data Repository Table'!$G:$G,'Revenue Analysis'!$D18,'Data Repository Table'!$D:$D,'Revenue Analysis'!G$10) -> 2241097.2 | H18: =SUMIFS('Data Repository Table'!$I:$I,'Data Repository Table'!$C:$C,'Revenue Analysis'!$A18,'Data Repository Table'!$B:$B,'Revenue Analysis'!$B18,'Data Repository Table'!$F:$F,'Revenue Analysis'!$C18,'Data Repository Table'!$G:$G,'Revenue Analysis'!$D18,'Data Repository Table'!$D:$D,'Revenue Analysis'!H$10) -> 2104393.5 | I18: =SUMIFS('Data Repository Table'!$I:$I,'Data Repository Table'!$C:$C,'Revenue Analysis'!$A18,'Data Repository Table'!$B:$B,'Revenue Analysis'!$B18,'Data Repository Table'!$F:$F,'Revenue Analysis'!$C18,'Data Repository Table'!$G:$G,'Revenue Analysis'!$D18,'Data Repository Table'!$D:$D,'Revenue Analysis'!I$10) -> 1921236.2 | J18: =SUMIFS('Data Repository Table'!$I:$I,'Data Repository Table'!$C:$C,'Revenue Analysis'!$A18,'Data Repository Table'!$B:$B,'Revenue Analysis'!$B18,'Data Repository Table'!$F:$F,'Revenue Analysis'!$C18,'Data Repository Table'!$G:$G,'Revenue Analysis'!$D18,'Data Repository Table'!$D:$D,'Revenue Analysis'!J$10) -> 2161522.2 | K18: =SUMIFS('Data Repository Table'!$I:$I,'Data Repository Table'!$C:$C,'Revenue Analysis'!$A18,'Data Repository Table'!$B:$B,'Revenue Analysis'!$B18,'Data Repository Table'!$F:$F,'Revenue Analysis'!$C18,'Data Repository Table'!$G:$G,'Revenue Analysis'!$D18,'Data Repository Table'!$D:$D,'Revenue Analysis'!K$10) -> 3104730.2 | L18: =SUMIFS('Data Repository Table'!$I:$I,'Data Repository Table'!$C:$C,'Revenue Analysis'!$A18,'Data Repository Table'!$B:$B,'Revenue Analysis'!$B18,'Data Repository Table'!$F:$F,'Revenue Analysis'!$C18,'Data Repository Table'!$G:$G,'Revenue Analysis'!$D18,'Data Repository Table'!$D:$D,'Revenue Analysis'!L$10) -> 2116798.7 | ... P18: =SUMIFS('Data Repository Table'!$I:$I,'Data Repository Table'!$C:$C,'Revenue Analysis'!$A18,'Data Repository Table'!$B:$B,'Revenue Analysis'!$B18,'Data Repository Table'!$F:$F,'Revenue Analysis'!$C18,'Data Repository Table'!$G:$G,'Revenue Analysis'!$D18,'Data Repository Table'!$D:$D,'Revenue Analysis'!P$10) -> 2245023.2 | Q18: =SUM(E18:P18) -> 27349354
A19: Surjek | B19: Revenue | C19: 001 Private Water Hedge Sales | D19: W-Transact (0212) - Hard | E19: =SUMIFS('Data Repository Table'!$I:$I,'Data Repository Table'!$C:$C,'Revenue Analysis'!$A19,'Data Repository Table'!$B:$B,'Revenue Analysis'!$B19,'Data Repository Table'!$F:$F,'Revenue Analysis'!$C19,'Data Repository Table'!$G:$G,'Revenue Analysis'!$D19,'Data Repository Table'!$D:$D,'Revenue Analysis'!E$10) -> 4813347.5 | F19: =SUMIFS('Data Repository Table'!$I:$I,'Data Repository Table'!$C:$C,'Revenue Analysis'!$A19,'Data Repository Table'!$B:$B,'Revenue Analysis'!$B19,'Data Repository Table'!$F:$F,'Revenue Analysis'!$C19,'Data Repository Table'!$G:$G,'Revenue Analysis'!$D19,'Data Repository Table'!$D:$D,'Revenue Analysis'!F$10) -> 4056754 | G19: =SUMIFS('Data Repository Table'!$I:$I,'Data Repository Table'!$C:$C,'Revenue Analysis'!$A19,'Data Repository Table'!$B:$B,'Revenue Analysis'!$B19,'Data Repository Table'!$F:$F,'Revenue Analysis'!$C19,'Data Repository Table'!$G:$G,'Revenue Analysis'!$D19,'Data Repository Table'!$D:$D,'Revenue Analysis'!G$10) -> 4482194.5 | H19: =SUMIFS('Data Repository Table'!$I:$I,'Data Repository Table'!$C:$C,'Revenue Analysis'!$A19,'Data Repository Table'!$B:$B,'Revenue Analysis'!$B19,'Data Repository Table'!$F:$F,'Revenue Analysis'!$C19,'Data Repository Table'!$G:$G,'Revenue Analysis'!$D19,'Data Repository Table'!$D:$D,'Revenue Analysis'!H$10) -> 4208787 | I19: =SUMIFS('Data Repository Table'!$I:$I,'Data Repository Table'!$C:$C,'Revenue Analysis'!$A19,'Data Repository Table'!$B:$B,'Revenue Analysis'!$B19,'Data Repository Table'!$F:$F,'Revenue Analysis'!$C19,'Data Repository Table'!$G:$G,'Revenue Analysis'!$D19,'Data Repository Table'!$D:$D,'Revenue Analysis'!I$10) -> 3842472.4 | J19: =SUMIFS('Data Repository Table'!$I:$I,'Data Repository Table'!$C:$C,'Revenue Analysis'!$A19,'Data Repository Table'!$B:$B,'Revenue Analysis'!$B19,'Data Repository Table'!$F:$F,'Revenue Analysis'!$C19,'Data Repository Table'!$G:$G,'Revenue Analysis'!$D19,'Data Repository Table'!$D:$D,'Revenue Analysis'!J$10) -> 4323044.3 | K19: =SUMIFS('Data Repository Table'!$I:$I,'Data Repository Table'!$C:$C,'Revenue Analysis'!$A19,'Data Repository Table'!$B:$B,'Revenue Analysis'!$B19,'Data Repository Table'!$F:$F,'Revenue Analysis'!$C19,'Data Repository Table'!$G:$G,'Revenue Analysis'!$D19,'Data Repository Table'!$D:$D,'Revenue Analysis'!K$10) -> 6209460.5 | L19: =SUMIFS('Data Repository Table'!$I:$I,'Data Repository Table'!$C:$C,'Revenue Analysis'!$A19,'Data Repository Table'!$B:$B,'Revenue Analysis'!$B19,'Data Repository Table'!$F:$F,'Revenue Analysis'!$C19,'Data Repository Table'!$G:$G,'Revenue Analysis'!$D19,'Data Repository Table'!$D:$D,'Revenue Analysis'!L$10) -> 4633597.4 | ... P19: =SUMIFS('Data Repository Table'!$I:$I,'Data Repository Table'!$C:$C,'Revenue Analysis'!$A19,'Data Repository Table'!$B:$B,'Revenue Analysis'!$B19,'Data Repository Table'!$F:$F,'Revenue Analysis'!$C19,'Data Repository Table'!$G:$G,'Revenue Analysis'!$D19,'Data Repository Table'!$D:$D,'Revenue Analysis'!P$10) -> 4490046.5 | Q19: =SUM(E19:P19) -> 55098708
A20: Surjek | B20: Revenue | C20: 002 Public Sales | D20: W-Transact (0211) - Soft | E20: =SUMIFS('Data Repository Table'!$I:$I,'Data Repository Table'!$C:$C,'Revenue Analysis'!$A20,'Data Repository Table'!$B:$B,'Revenue Analysis'!$B20,'Data Repository Table'!$F:$F,'Revenue Analysis'!$C20,'Data Repository Table'!$G:$G,'Revenue Analysis'!$D20,'Data Repository Table'!$D:$D,'Revenue Analysis'!E$10) -> 2117872.9 | F20: =SUMIFS('Data Repository Table'!$I:$I,'Data Repository Table'!$C:$C,'Revenue Analysis'!$A20,'Data Repository Table'!$B:$B,'Revenue Analysis'!$B20,'Data Repository Table'!$F:$F,'Revenue Analysis'!$C20,'Data Repository Table'!$G:$G,'Revenue Analysis'!$D20,'Data Repository Table'!$D:$D,'Revenue Analysis'!F$10) -> 1784971.8 | G20: =SUMIFS('Data Repository Table'!$I:$I,'Data Repository Table'!$C:$C,'Revenue Analysis'!$A20,'Data Repository Table'!$B:$B,'Revenue Analysis'!$B20,'Data Repository Table'!$F:$F,'Revenue Analysis'!$C20,'Data Repository Table'!$G:$G,'Revenue Analysis'!$D20,'Data Repository Table'!$D:$D,'Revenue Analysis'!G$10) -> 1972165.6 | H20: =SUMIFS('Data Repository Table'!$I:$I,'Data Repository Table'!$C:$C,'Revenue Analysis'!$A20,'Data Repository Table'!$B:$B,'Revenue Analysis'!$B20,'Data Repository Table'!$F:$F,'Revenue Analysis'!$C20,'Data Repository Table'!$G:$G,'Revenue Analysis'!$D20,'Data Repository Table'!$D:$D,'Revenue Analysis'!H$10) -> 1851866.3 | I20: =SUMIFS('Data Repository Table'!$I:$I,'Data Repository Table'!$C:$C,'Revenue Analysis'!$A20,'Data Repository Table'!$B:$B,'Revenue Analysis'!$B20,'Data Repository Table'!$F:$F,'Revenue Analysis'!$C20,'Data Repository Table'!$G:$G,'Revenue Analysis'!$D20,'Data Repository Table'!$D:$D,'Revenue Analysis'!I$10) -> 1690687.9 | J20: =SUMIFS('Data Repository Table'!$I:$I,'Data Repository Table'!$C:$C,'Revenue Analysis'!$A20,'Data Repository Table'!$B:$B,'Revenue Analysis'!$B20,'Data Repository Table'!$F:$F,'Revenue Analysis'!$C20,'Data Repository Table'!$G:$G,'Revenue Analysis'!$D20,'Data Repository Table'!$D:$D,'Revenue Analysis'!J$10) -> 1902139.5 | K20: =SUMIFS('Data Repository Table'!$I:$I,'Data Repository Table'!$C:$C,'Revenue Analysis'!$A20,'Data Repository Table'!$B:$B,'Revenue Analysis'!$B20,'Data Repository Table'!$F:$F,'Revenue Analysis'!$C20,'Data Repository Table'!$G:$G,'Revenue Analysis'!$D20,'Data Repository Table'!$D:$D,'Revenue Analysis'!K$10) -> 2732162.6 | L20: =SUMIFS('Data Repository Table'!$I:$I,'Data Repository Table'!$C:$C,'Revenue Analysis'!$A20,'Data Repository Table'!$B:$B,'Revenue Analysis'!$B20,'Data Repository Table'!$F:$F,'Revenue Analysis'!$C20,'Data Repository Table'!$G:$G,'Revenue Analysis'!$D20,'Data Repository Table'!$D:$D,'Revenue Analysis'!L$10) -> 2478782.9 | ... P20: =SUMIFS('Data Repository Table'!$I:$I,'Data Repository Table'!$C:$C,'Revenue Analysis'!$A20,'Data Repository Table'!$B:$B,'Revenue Analysis'!$B20,'Data Repository Table'!$F:$F,'Revenue Analysis'!$C20,'Data Repository Table'!$G:$G,'Revenue Analysis'!$D20,'Data Repository Table'!$D:$D,'Revenue Analysis'!P$10) -> 1975620.4 | Q20: =SUM(E20:P20) -> 24683432
A21: Surjek | B21: Revenue | C21: 002 Public Sales | D21: W-Transact (0212) - Hard | E21: =SUMIFS('Data Repository Table'!$I:$I,'Data Repository Table'!$C:$C,'Revenue Analysis'!$A21,'Data Repository Table'!$B:$B,'Revenue Analysis'!$B21,'Data Repository Table'!$F:$F,'Revenue Analysis'!$C21,'Data Repository Table'!$G:$G,'Revenue Analysis'!$D21,'Data Repository Table'!$D:$D,'Revenue Analysis'!E$10) -> 3850678 | F21: =SUMIFS('Data Repository Table'!$I:$I,'Data Repository Table'!$C:$C,'Revenue Analysis'!$A21,'Data Repository Table'!$B:$B,'Revenue Analysis'!$B21,'Data Repository Table'!$F:$F,'Revenue Analysis'!$C21,'Data Repository Table'!$G:$G,'Revenue Analysis'!$D21,'Data Repository Table'!$D:$D,'Revenue Analysis'!F$10) -> 3245403.2 | G21: =SUMIFS('Data Repository Table'!$I:$I,'Data Repository Table'!$C:$C,'Revenue Analysis'!$A21,'Data Repository Table'!$B:$B,'Revenue Analysis'!$B21,'Data Repository Table'!$F:$F,'Revenue Analysis'!$C21,'Data Repository Table'!$G:$G,'Revenue Analysis'!$D21,'Data Repository Table'!$D:$D,'Revenue Analysis'!G$10) -> 3585755.6 | H21: =SUMIFS('Data Repository Table'!$I:$I,'Data Repository Table'!$C:$C,'Revenue Analysis'!$A21,'Data Repository Table'!$B:$B,'Revenue Analysis'!$B21,'Data Repository Table'!$F:$F,'Revenue Analysis'!$C21,'Data Repository Table'!$G:$G,'Revenue Analysis'!$D21,'Data Repository Table'!$D:$D,'Revenue Analysis'!H$10) -> 3367029.6 | I21: =SUMIFS('Data Repository Table'!$I:$I,'Data Repository Table'!$C:$C,'Revenue Analysis'!$A21,'Data Repository Table'!$B:$B,'Revenue Analysis'!$B21,'Data Repository Table'!$F:$F,'Revenue Analysis'!$C21,'Data Repository Table'!$G:$G,'Revenue Analysis'!$D21,'Data Repository Table'!$D:$D,'Revenue Analysis'!I$10) -> 3073978 | J21: =SUMIFS('Data Repository Table'!$I:$I,'Data Repository Table'!$C:$C,'Revenue Analysis'!$A21,'Data Repository Table'!$B:$B,'Revenue Analysis'!$B21,'Data Repository Table'!$F:$F,'Revenue Analysis'!$C21,'Data Repository Table'!$G:$G,'Revenue Analysis'!$D21,'Data Repository Table'!$D:$D,'Revenue Analysis'!J$10) -> 3458435.5 | K21: =SUMIFS('Data Repository Table'!$I:$I,'Data Repository Table'!$C:$C,'Revenue Analysis'!$A21,'Data Repository Table'!$B:$B,'Revenue Analysis'!$B21,'Data Repository Table'!$F:$F,'Revenue Analysis'!$C21,'Data Repository Table'!$G:$G,'Revenue Analysis'!$D21,'Data Repository Table'!$D:$D,'Revenue Analysis'!K$10) -> 4967568.4 | L21: =SUMIFS('Data Repository Table'!$I:$I,'Data Repository Table'!$C:$C,'Revenue Analysis'!$A21,'Data Repository Table'!$B:$B,'Revenue Analysis'!$B21,'Data Repository Table'!$F:$F,'Revenue Analysis'!$C21,'Data Repository Table'!$G:$G,'Revenue Analysis'!$D21,'Data Repository Table'!$D:$D,'Revenue Analysis'!L$10) -> 4506877.9 | ... P21: =SUMIFS('Data Repository Table'!$I:$I,'Data Repository Table'!$C:$C,'Revenue Analysis'!$A21,'Data Repository Table'!$B:$B,'Revenue Analysis'!$B21,'Data Repository Table'!$F:$F,'Revenue Analysis'!$C21,'Data Repository Table'!$G:$G,'Revenue Analysis'!$D21,'Data Repository Table'!$D:$D,'Revenue Analysis'!P$10) -> 3592037.2 | Q21: =SUM(E21:P21) -> 45878966
A22: Surjek | B22: Revenue | C22: 003 Residential Sales | D22: W-Transact (0211) - Soft | E22: =SUMIFS('Data Repository Table'!$I:$I,'Data Repository Table'!$C:$C,'Revenue Analysis'!$A22,'Data Repository Table'!$B:$B,'Revenue Analysis'!$B22,'Data Repository Table'!$F:$F,'Revenue Analysis'!$C22,'Data Repository Table'!$G:$G,'Revenue Analysis'!$D22,'Data Repository Table'!$D:$D,'Revenue Analysis'!E$10) -> 4139478.8 | F22: =SUMIFS('Data Repository Table'!$I:$I,'Data Repository Table'!$C:$C,'Revenue Analysis'!$A22,'Data Repository Table'!$B:$B,'Revenue Analysis'!$B22,'Data Repository Table'!$F:$F,'Revenue Analysis'!$C22,'Data Repository Table'!$G:$G,'Revenue Analysis'!$D22,'Data Repository Table'!$D:$D,'Revenue Analysis'!F$10) -> 3488808.4 | G22: =SUMIFS('Data Repository Table'!$I:$I,'Data Repository Table'!$C:$C,'Revenue Analysis'!$A22,'Data Repository Table'!$B:$B,'Revenue Analysis'!$B22,'Data Repository Table'!$F:$F,'Revenue Analysis'!$C22,'Data Repository Table'!$G:$G,'Revenue Analysis'!$D22,'Data Repository Table'!$D:$D,'Revenue Analysis'!G$10) -> 3854687.3 | H22: =SUMIFS('Data Repository Table'!$I:$I,'Data Repository Table'!$C:$C,'Revenue Analysis'!$A22,'Data Repository Table'!$B:$B,'Revenue Analysis'!$B22,'Data Repository Table'!$F:$F,'Revenue Analysis'!$C22,'Data Repository Table'!$G:$G,'Revenue Analysis'!$D22,'Data Repository Table'!$D:$D,'Revenue Analysis'!H$10) -> 3619556.8 | I22: =SUMIFS('Data Repository Table'!$I:$I,'Data Repository Table'!$C:$C,'Revenue Analysis'!$A22,'Data Repository Table'!$B:$B,'Revenue Analysis'!$B22,'Data Repository Table'!$F:$F,'Revenue Analysis'!$C22,'Data Repository Table'!$G:$G,'Revenue Analysis'!$D22,'Data Repository Table'!$D:$D,'Revenue Analysis'!I$10) -> 3304526.3 | J22: =SUMIFS('Data Repository Table'!$I:$I,'Data Repository Table'!$C:$C,'Revenue Analysis'!$A22,'Data Repository Table'!$B:$B,'Revenue Analysis'!$B22,'Data Repository Table'!$F:$F,'Revenue Analysis'!$C22,'Data Repository Table'!$G:$G,'Revenue Analysis'!$D22,'Data Repository Table'!$D:$D,'Revenue Analysis'!J$10) -> 3717818.1 | K22: =SUMIFS('Data Repository Table'!$I:$I,'Data Repository Table'!$C:$C,'Revenue Analysis'!$A22,'Data Repository Table'!$B:$B,'Revenue Analysis'!$B22,'Data Repository Table'!$F:$F,'Revenue Analysis'!$C22,'Data Repository Table'!$G:$G,'Revenue Analysis'!$D22,'Data Repository Table'!$D:$D,'Revenue Analysis'!K$10) -> 5340136 | L22: =SUMIFS('Data Repository Table'!$I:$I,'Data Repository Table'!$C:$C,'Revenue Analysis'!$A22,'Data Repository Table'!$B:$B,'Revenue Analysis'!$B22,'Data Repository Table'!$F:$F,'Revenue Analysis'!$C22,'Data Repository Table'!$G:$G,'Revenue Analysis'!$D22,'Data Repository Table'!$D:$D,'Revenue Analysis'!L$10) -> 4844893.8 | ... P22: =SUMIFS('Data Repository Table'!$I:$I,'Data Repository Table'!$C:$C,'Revenue Analysis'!$A22,'Data Repository Table'!$B:$B,'Revenue Analysis'!$B22,'Data Repository Table'!$F:$F,'Revenue Analysis'!$C22,'Data Repository Table'!$G:$G,'Revenue Analysis'!$D22,'Data Repository Table'!$D:$D,'Revenue Analysis'!P$10) -> 3861440 | Q22: =SUM(E22:P22) -> 49244889
A24: Jutik | B24: Revenue | C24: 001 Private Water Hedge Sales | D24: W-Transact (0211) - Soft | E24: =SUMIFS('Data Repository Table'!$I:$I,'Data Repository Table'!$C:$C,'Revenue Analysis'!$A24,'Data Repository Table'!$B:$B,'Revenue Analysis'!$B24,'Data Repository Table'!$F:$F,'Revenue Analysis'!$C24,'Data Repository Table'!$G:$G,'Revenue Analysis'!$D24,'Data Repository Table'!$D:$D,'Revenue Analysis'!E$10) -> 1766228.7 | F24: =SUMIFS('Data Repository Table'!$I:$I,'Data Repository Table'!$C:$C,'Revenue Analysis'!$A24,'Data Repository Table'!$B:$B,'Revenue Analysis'!$B24,'Data Repository Table'!$F:$F,'Revenue Analysis'!$C24,'Data Repository Table'!$G:$G,'Revenue Analysis'!$D24,'Data Repository Table'!$D:$D,'Revenue Analysis'!F$10) -> 1951422.8 | G24: =SUMIFS('Data Repository Table'!$I:$I,'Data Repository Table'!$C:$C,'Revenue Analysis'!$A24,'Data Repository Table'!$B:$B,'Revenue Analysis'!$B24,'Data Repository Table'!$F:$F,'Revenue Analysis'!$C24,'Data Repository Table'!$G:$G,'Revenue Analysis'!$D24,'Data Repository Table'!$D:$D,'Revenue Analysis'!G$10) -> 1699371.2 | H24: =SUMIFS('Data Repository Table'!$I:$I,'Data Repository Table'!$C:$C,'Revenue Analysis'!$A24,'Data Repository Table'!$B:$B,'Revenue Analysis'!$B24,'Data Repository Table'!$F:$F,'Revenue Analysis'!$C24,'Data Repository Table'!$G:$G,'Revenue Analysis'!$D24,'Data Repository Table'!$D:$D,'Revenue Analysis'!H$10) -> 1502189.2 | I24: =SUMIFS('Data Repository Table'!$I:$I,'Data Repository Table'!$C:$C,'Revenue Analysis'!$A24,'Data Repository Table'!$B:$B,'Revenue Analysis'!$B24,'Data Repository Table'!$F:$F,'Revenue Analysis'!$C24,'Data Repository Table'!$G:$G,'Revenue Analysis'!$D24,'Data Repository Table'!$D:$D,'Revenue Analysis'!I$10) -> 1650239.5 | J24: =SUMIFS('Data Repository Table'!$I:$I,'Data Repository Table'!$C:$C,'Revenue Analysis'!$A24,'Data Repository Table'!$B:$B,'Revenue Analysis'!$B24,'Data Repository Table'!$F:$F,'Revenue Analysis'!$C24,'Data Repository Table'!$G:$G,'Revenue Analysis'!$D24,'Data Repository Table'!$D:$D,'Revenue Analysis'!J$10) -> 1406546.1 | K24: =SUMIFS('Data Repository Table'!$I:$I,'Data Repository Table'!$C:$C,'Revenue Analysis'!$A24,'Data Repository Table'!$B:$B,'Revenue Analysis'!$B24,'Data Repository Table'!$F:$F,'Revenue Analysis'!$C24,'Data Repository Table'!$G:$G,'Revenue Analysis'!$D24,'Data Repository Table'!$D:$D,'Revenue Analysis'!K$10) -> 2151540.2 | L24: =SUMIFS('Data Repository Table'!$I:$I,'Data Repository Table'!$C:$C,'Revenue Analysis'!$A24,'Data Repository Table'!$B:$B,'Revenue Analysis'!$B24,'Data Repository Table'!$F:$F,'Revenue Analysis'!$C24,'Data Repository Table'!$G:$G,'Revenue Analysis'!$D24,'Data Repository Table'!$D:$D,'Revenue Analysis'!L$10) -> 2191228.2 | ... P24: =SUMIFS('Data Repository Table'!$I:$I,'Data Repository Table'!$C:$C,'Revenue Analysis'!$A24,'Data Repository Table'!$B:$B,'Revenue Analysis'!$B24,'Data Repository Table'!$F:$F,'Revenue Analysis'!$C24,'Data Repository Table'!$G:$G,'Revenue Analysis'!$D24,'Data Repository Table'!$D:$D,'Revenue Analysis'!P$10) -> 2197266.9 | Q24: =SUM(E24:P24) -> 22620170
A25: Jutik | B25: Revenue | C25: 001 Private Water Hedge Sales | D25: W-Transact (0212) - Hard | E25: =SUMIFS('Data Repository Table'!$I:$I,'Data Repository Table'!$C:$C,'Revenue Analysis'!$A25,'Data Repository Table'!$B:$B,'Revenue Analysis'!$B25,'Data Repository Table'!$F:$F,'Revenue Analysis'!$C25,'Data Repository Table'!$G:$G,'Revenue Analysis'!$D25,'Data Repository Table'!$D:$D,'Revenue Analysis'!E$10) -> 3532457.4 | F25: =SUMIFS('Data Repository Table'!$I:$I,'Data Repository Table'!$C:$C,'Revenue Analysis'!$A25,'Data Repository Table'!$B:$B,'Revenue Analysis'!$B25,'Data Repository Table'!$F:$F,'Revenue Analysis'!$C25,'Data Repository Table'!$G:$G,'Revenue Analysis'!$D25,'Data Repository Table'!$D:$D,'Revenue Analysis'!F$10) -> 3902845.5 | G25: =SUMIFS('Data Repository Table'!$I:$I,'Data Repository Table'!$C:$C,'Revenue Analysis'!$A25,'Data Repository Table'!$B:$B,'Revenue Analysis'!$B25,'Data Repository Table'!$F:$F,'Revenue Analysis'!$C25,'Data Repository Table'!$G:$G,'Revenue Analysis'!$D25,'Data Repository Table'!$D:$D,'Revenue Analysis'!G$10) -> 3398742.5 | H25: =SUMIFS('Data Repository Table'!$I:$I,'Data Repository Table'!$C:$C,'Revenue Analysis'!$A25,'Data Repository Table'!$B:$B,'Revenue Analysis'!$B25,'Data Repository Table'!$F:$F,'Revenue Analysis'!$C25,'Data Repository Table'!$G:$G,'Revenue Analysis'!$D25,'Data Repository Table'!$D:$D,'Revenue Analysis'!H$10) -> 3004378.4 | I25: =SUMIFS('Data Repository Table'!$I:$I,'Data Repository Table'!$C:$C,'Revenue Analysis'!$A25,'Data Repository Table'!$B:$B,'Revenue Analysis'!$B25,'Data Repository Table'!$F:$F,'Revenue Analysis'!$C25,'Data Repository Table'!$G:$G,'Revenue Analysis'!$D25,'Data Repository Table'!$D:$D,'Revenue Analysis'!I$10) -> 3300479 | J25: =SUMIFS('Data Repository Table'!$I:$I,'Data Repository Table'!$C:$C,'Revenue Analysis'!$A25,'Data Repository Table'!$B:$B,'Revenue Analysis'!$B25,'Data Repository Table'!$F:$F,'Revenue Analysis'!$C25,'Data Repository Table'!$G:$G,'Revenue Analysis'!$D25,'Data Repository Table'!$D:$D,'Revenue Analysis'!J$10) -> 2813092.2 | K25: =SUMIFS('Data Repository Table'!$I:$I,'Data Repository Table'!$C:$C,'Revenue Analysis'!$A25,'Data Repository Table'!$B:$B,'Revenue Analysis'!$B25,'Data Repository Table'!$F:$F,'Revenue Analysis'!$C25,'Data Repository Table'!$G:$G,'Revenue Analysis'!$D25,'Data Repository Table'!$D:$D,'Revenue Analysis'!K$10) -> 4303080.4 | L25: =SUMIFS('Data Repository Table'!$I:$I,'Data Repository Table'!$C:$C,'Revenue Analysis'!$A25,'Data Repository Table'!$B:$B,'Revenue Analysis'!$B25,'Data Repository Table'!$F:$F,'Revenue Analysis'!$C25,'Data Repository Table'!$G:$G,'Revenue Analysis'!$D25,'Data Repository Table'!$D:$D,'Revenue Analysis'!L$10) -> 4382456.5 | ... P25: =SUMIFS('Data Repository Table'!$I:$I,'Data Repository Table'!$C:$C,'Revenue Analysis'!$A25,'Data Repository Table'!$B:$B,'Revenue Analysis'!$B25,'Data Repository Table'!$F:$F,'Revenue Analysis'!$C25,'Data Repository Table'!$G:$G,'Revenue Analysis'!$D25,'Data Repository Table'!$D:$D,'Revenue Analysis'!P$10) -> 4394533.8 | Q25: =SUM(E25:P25) -> 45240340
... A28: Jutik | B28: Revenue | C28: 003 Residential Sales | D28: W-Transact (0211) - Soft | E28: =SUMIFS('Data Repository Table'!$I:$I,'Data Repository Table'!$C:$C,'Revenue Analysis'!$A28,'Data Repository Table'!$B:$B,'Revenue Analysis'!$B28,'Data Repository Table'!$F:$F,'Revenue Analysis'!$C28,'Data Repository Table'!$G:$G,'Revenue Analysis'!$D28,'Data Repository Table'!$D:$D,'Revenue Analysis'!E$10) -> 3037913.4 | F28: =SUMIFS('Data Repository Table'!$I:$I,'Data Repository Table'!$C:$C,'Revenue Analysis'!$A28,'Data Repository Table'!$B:$B,'Revenue Analysis'!$B28,'Data Repository Table'!$F:$F,'Revenue Analysis'!$C28,'Data Repository Table'!$G:$G,'Revenue Analysis'!$D28,'Data Repository Table'!$D:$D,'Revenue Analysis'!F$10) -> 3356447.1 | G28: =SUMIFS('Data Repository Table'!$I:$I,'Data Repository Table'!$C:$C,'Revenue Analysis'!$A28,'Data Repository Table'!$B:$B,'Revenue Analysis'!$B28,'Data Repository Table'!$F:$F,'Revenue Analysis'!$C28,'Data Repository Table'!$G:$G,'Revenue Analysis'!$D28,'Data Repository Table'!$D:$D,'Revenue Analysis'!G$10) -> 2922918.5 | H28: =SUMIFS('Data Repository Table'!$I:$I,'Data Repository Table'!$C:$C,'Revenue Analysis'!$A28,'Data Repository Table'!$B:$B,'Revenue Analysis'!$B28,'Data Repository Table'!$F:$F,'Revenue Analysis'!$C28,'Data Repository Table'!$G:$G,'Revenue Analysis'!$D28,'Data Repository Table'!$D:$D,'Revenue Analysis'!H$10) -> 2583765.4 | I28: =SUMIFS('Data Repository Table'!$I:$I,'Data Repository Table'!$C:$C,'Revenue Analysis'!$A28,'Data Repository Table'!$B:$B,'Revenue Analysis'!$B28,'Data Repository Table'!$F:$F,'Revenue Analysis'!$C28,'Data Repository Table'!$G:$G,'Revenue Analysis'!$D28,'Data Repository Table'!$D:$D,'Revenue Analysis'!I$10) -> 2838412 | J28: =SUMIFS('Data Repository Table'!$I:$I,'Data Repository Table'!$C:$C,'Revenue Analysis'!$A28,'Data Repository Table'!$B:$B,'Revenue Analysis'!$B28,'Data Repository Table'!$F:$F,'Revenue Analysis'!$C28,'Data Repository Table'!$G:$G,'Revenue Analysis'!$D28,'Data Repository Table'!$D:$D,'Revenue Analysis'!J$10) -> 2419259.3 | K28: =SUMIFS('Data Repository Table'!$I:$I,'Data Repository Table'!$C:$C,'Revenue Analysis'!$A28,'Data Repository Table'!$B:$B,'Revenue Analysis'!$B28,'Data Repository Table'!$F:$F,'Revenue Analysis'!$C28,'Data Repository Table'!$G:$G,'Revenue Analysis'!$D28,'Data Repository Table'!$D:$D,'Revenue Analysis'!K$10) -> 3700649.1 | L28: =SUMIFS('Data Repository Table'!$I:$I,'Data Repository Table'!$C:$C,'Revenue Analysis'!$A28,'Data Repository Table'!$B:$B,'Revenue Analysis'!$B28,'Data Repository Table'!$F:$F,'Revenue Analysis'!$C28,'Data Repository Table'!$G:$G,'Revenue Analysis'!$D28,'Data Repository Table'!$D:$D,'Revenue Analysis'!L$10) -> 3768912.5 | ... P28: =SUMIFS('Data Repository Table'!$I:$I,'Data Repository Table'!$C:$C,'Revenue Analysis'!$A28,'Data Repository Table'!$B:$B,'Revenue Analysis'!$B28,'Data Repository Table'!$F:$F,'Revenue Analysis'!$C28,'Data Repository Table'!$G:$G,'Revenue Analysis'!$D28,'Data Repository Table'!$D:$D,'Revenue Analysis'!P$10) -> 3079299.1 | Q28: =SUM(E28:P28) -> 37706693
A30: You've now calculated the Revenues for each of the three desalination plants (Kootha, Surjek and Jutik). This has given you a micro-view of the trends, but let's take a look at the macro-revenue trends and view all this information aggregated together. In the next question, you're aggregating the revenues at the Accounting Code Centre Level, where in the previous question, we went all the way to the Accounting Code Centre Element Level.
A31: Q2. Just as you did for Q1 above, calculate the monthly revenues for Kootha, Surjek and Jutik at the Accounting Code Centre Level and put this in the table below.
A32: Unit | B32: Value Driver | C32: Accounting Code Centre | E32: 41456 | F32: 41487 | G32: 41518 | H32: 41548 | I32: 41579 | J32: 41609 | K32: 41640 | L32: 41671 | M32: 41699 | N32: 41730 | O32: 41760 | P32: 41791
Q33: Total
A34: Kootha | B34: Revenue | C34: 001 Private Water Hedge Sales | E34: =SUMIFS('Data Repository Table'!$I:$I,'Data Repository Table'!$C:$C,'Revenue Analysis'!$A34,'Data Repository Table'!$B:$B,'Revenue Analysis'!$B34,'Data Repository Table'!$F:$F,'Revenue Analysis'!$C34,'Data Repository Table'!$D:$D,'Revenue Analysis'!E$32) -> 3094537 | F34: =SUMIFS('Data Repository Table'!$I:$I,'Data Repository Table'!$C:$C,'Revenue Analysis'!$A34,'Data Repository Table'!$B:$B,'Revenue Analysis'!$B34,'Data Repository Table'!$F:$F,'Revenue Analysis'!$C34,'Data Repository Table'!$D:$D,'Revenue Analysis'!F$32) -> 2980521.8 | G34: =SUMIFS('Data Repository Table'!$I:$I,'Data Repository Table'!$C:$C,'Revenue Analysis'!$A34,'Data Repository Table'!$B:$B,'Revenue Analysis'!$B34,'Data Repository Table'!$F:$F,'Revenue Analysis'!$C34,'Data Repository Table'!$D:$D,'Revenue Analysis'!G$32) -> 2752413.7 | H34: =SUMIFS('Data Repository Table'!$I:$I,'Data Repository Table'!$C:$C,'Revenue Analysis'!$A34,'Data Repository Table'!$B:$B,'Revenue Analysis'!$B34,'Data Repository Table'!$F:$F,'Revenue Analysis'!$C34,'Data Repository Table'!$D:$D,'Revenue Analysis'!H$32) -> 2732151.9 | I34: =SUMIFS('Data Repository Table'!$I:$I,'Data Repository Table'!$C:$C,'Revenue Analysis'!$A34,'Data Repository Table'!$B:$B,'Revenue Analysis'!$B34,'Data Repository Table'!$F:$F,'Revenue Analysis'!$C34,'Data Repository Table'!$D:$D,'Revenue Analysis'!I$32) -> 2885028 | J34: =SUMIFS('Data Repository Table'!$I:$I,'Data Repository Table'!$C:$C,'Revenue Analysis'!$A34,'Data Repository Table'!$B:$B,'Revenue Analysis'!$B34,'Data Repository Table'!$F:$F,'Revenue Analysis'!$C34,'Data Repository Table'!$D:$D,'Revenue Analysis'!J$32) -> 2815308.4 | K34: =SUMIFS('Data Repository Table'!$I:$I,'Data Repository Table'!$C:$C,'Revenue Analysis'!$A34,'Data Repository Table'!$B:$B,'Revenue Analysis'!$B34,'Data Repository Table'!$F:$F,'Revenue Analysis'!$C34,'Data Repository Table'!$D:$D,'Revenue Analysis'!K$32) -> 4092821.4 | L34: =SUMIFS('Data Repository Table'!$I:$I,'Data Repository Table'!$C:$C,'Revenue Analysis'!$A34,'Data Repository Table'!$B:$B,'Revenue Analysis'!$B34,'Data Repository Table'!$F:$F,'Revenue Analysis'!$C34,'Data Repository Table'!$D:$D,'Revenue Analysis'!L$32) -> 3622839.6 | ... P34: =SUMIFS('Data Repository Table'!$I:$I,'Data Repository Table'!$C:$C,'Revenue Analysis'!$A34,'Data Repository Table'!$B:$B,'Revenue Analysis'!$B34,'Data Repository Table'!$F:$F,'Revenue Analysis'!$C34,'Data Repository Table'!$D:$D,'Revenue Analysis'!P$32) -> 2712379.2 | Q34: =SUM(E34:P34) -> 37118739
A35: Kootha | B35: Revenue | C35: 002 Public Sales | E35: =SUMIFS('Data Repository Table'!$I:$I,'Data Repository Table'!$C:$C,'Revenue Analysis'!$A35,'Data Repository Table'!$B:$B,'Revenue Analysis'!$B35,'Data Repository Table'!$F:$F,'Revenue Analysis'!$C35,'Data Repository Table'!$D:$D,'Revenue Analysis'!E$32) -> 1523285.8 | F35: =SUMIFS('Data Repository Table'!$I:$I,'Data Repository Table'!$C:$C,'Revenue Analysis'!$A35,'Data Repository Table'!$B:$B,'Revenue Analysis'!$B35,'Data Repository Table'!$F:$F,'Revenue Analysis'!$C35,'Data Repository Table'!$D:$D,'Revenue Analysis'!F$32) -> 1467161.9 | G35: =SUMIFS('Data Repository Table'!$I:$I,'Data Repository Table'!$C:$C,'Revenue Analysis'!$A35,'Data Repository Table'!$B:$B,'Revenue Analysis'!$B35,'Data Repository Table'!$F:$F,'Revenue Analysis'!$C35,'Data Repository Table'!$D:$D,'Revenue Analysis'!G$32) -> 1354875.7 | H35: =SUMIFS('Data Repository Table'!$I:$I,'Data Repository Table'!$C:$C,'Revenue Analysis'!$A35,'Data Repository Table'!$B:$B,'Revenue Analysis'!$B35,'Data Repository Table'!$F:$F,'Revenue Analysis'!$C35,'Data Repository Table'!$D:$D,'Revenue Analysis'!H$32) -> 1344901.8 | I35: =SUMIFS('Data Repository Table'!$I:$I,'Data Repository Table'!$C:$C,'Revenue Analysis'!$A35,'Data Repository Table'!$B:$B,'Revenue Analysis'!$B35,'Data Repository Table'!$F:$F,'Revenue Analysis'!$C35,'Data Repository Table'!$D:$D,'Revenue Analysis'!I$32) -> 1420155 | J35: =SUMIFS('Data Repository Table'!$I:$I,'Data Repository Table'!$C:$C,'Revenue Analysis'!$A35,'Data Repository Table'!$B:$B,'Revenue Analysis'!$B35,'Data Repository Table'!$F:$F,'Revenue Analysis'!$C35,'Data Repository Table'!$D:$D,'Revenue Analysis'!J$32) -> 1385835.5 | K35: =SUMIFS('Data Repository Table'!$I:$I,'Data Repository Table'!$C:$C,'Revenue Analysis'!$A35,'Data Repository Table'!$B:$B,'Revenue Analysis'!$B35,'Data Repository Table'!$F:$F,'Revenue Analysis'!$C35,'Data Repository Table'!$D:$D,'Revenue Analysis'!K$32) -> 2014691.3 | L35: =SUMIFS('Data Repository Table'!$I:$I,'Data Repository Table'!$C:$C,'Revenue Analysis'!$A35,'Data Repository Table'!$B:$B,'Revenue Analysis'!$B35,'Data Repository Table'!$F:$F,'Revenue Analysis'!$C35,'Data Repository Table'!$D:$D,'Revenue Analysis'!L$32) -> 1783342.8 | ... P35: =SUMIFS('Data Repository Table'!$I:$I,'Data Repository Table'!$C:$C,'Revenue Analysis'!$A35,'Data Repository Table'!$B:$B,'Revenue Analysis'!$B35,'Data Repository Table'!$F:$F,'Revenue Analysis'!$C35,'Data Repository Table'!$D:$D,'Revenue Analysis'!P$32) -> 1335168.7 | Q35: =SUM(E35:P35) -> 18271699
A36: Kootha | B36: Revenue | C36: 003 Residential Sales | E36: =SUMIFS('Data Repository Table'!$I:$I,'Data Repository Table'!$C:$C,'Revenue Analysis'!$A36,'Data Repository Table'!$B:$B,'Revenue Analysis'!$B36,'Data Repository Table'!$F:$F,'Revenue Analysis'!$C36,'Data Repository Table'!$D:$D,'Revenue Analysis'!E$32) -> 1296758.4 | F36: =SUMIFS('Data Repository Table'!$I:$I,'Data Repository Table'!$C:$C,'Revenue Analysis'!$A36,'Data Repository Table'!$B:$B,'Revenue Analysis'!$B36,'Data Repository Table'!$F:$F,'Revenue Analysis'!$C36,'Data Repository Table'!$D:$D,'Revenue Analysis'!F$32) -> 1248980.6 | G36: =SUMIFS('Data Repository Table'!$I:$I,'Data Repository Table'!$C:$C,'Revenue Analysis'!$A36,'Data Repository Table'!$B:$B,'Revenue Analysis'!$B36,'Data Repository Table'!$F:$F,'Revenue Analysis'!$C36,'Data Repository Table'!$D:$D,'Revenue Analysis'!G$32) -> 1153392.4 | H36: =SUMIFS('Data Repository Table'!$I:$I,'Data Repository Table'!$C:$C,'Revenue Analysis'!$A36,'Data Repository Table'!$B:$B,'Revenue Analysis'!$B36,'Data Repository Table'!$F:$F,'Revenue Analysis'!$C36,'Data Repository Table'!$D:$D,'Revenue Analysis'!H$32) -> 1144901.8 | I36: =SUMIFS('Data Repository Table'!$I:$I,'Data Repository Table'!$C:$C,'Revenue Analysis'!$A36,'Data Repository Table'!$B:$B,'Revenue Analysis'!$B36,'Data Repository Table'!$F:$F,'Revenue Analysis'!$C36,'Data Repository Table'!$D:$D,'Revenue Analysis'!I$32) -> 1208964.1 | J36: =SUMIFS('Data Repository Table'!$I:$I,'Data Repository Table'!$C:$C,'Revenue Analysis'!$A36,'Data Repository Table'!$B:$B,'Revenue Analysis'!$B36,'Data Repository Table'!$F:$F,'Revenue Analysis'!$C36,'Data Repository Table'!$D:$D,'Revenue Analysis'!J$32) -> 1179748.3 | K36: =SUMIFS('Data Repository Table'!$I:$I,'Data Repository Table'!$C:$C,'Revenue Analysis'!$A36,'Data Repository Table'!$B:$B,'Revenue Analysis'!$B36,'Data Repository Table'!$F:$F,'Revenue Analysis'!$C36,'Data Repository Table'!$D:$D,'Revenue Analysis'!K$32) -> 1715087 | L36: =SUMIFS('Data Repository Table'!$I:$I,'Data Repository Table'!$C:$C,'Revenue Analysis'!$A36,'Data Repository Table'!$B:$B,'Revenue Analysis'!$B36,'Data Repository Table'!$F:$F,'Revenue Analysis'!$C36,'Data Repository Table'!$D:$D,'Revenue Analysis'!L$32) -> 1518142.3 | ... P36: =SUMIFS('Data Repository Table'!$I:$I,'Data Repository Table'!$C:$C,'Revenue Analysis'!$A36,'Data Repository Table'!$B:$B,'Revenue Analysis'!$B36,'Data Repository Table'!$F:$F,'Revenue Analysis'!$C36,'Data Repository Table'!$D:$D,'Revenue Analysis'!P$32) -> 1136616 | Q36: =SUM(E36:P36) -> 15554519
